Workbook

Sheet HPS
A1: PEMERINTAH PROVINSI DAERAH KHUSUS IBUKOTA JAKARTA
A2: DINAS PENDIDIKAN
A3: SEKOLAH DASAR NEGERI KEBON KOSONG 09
A4: Jl. Kemayoran Gempol no.32 RT 015.05
D5: Jakarta Pusat 10630 email :sdnkk05pg@gmail.com
A8: HARGA PERKIRAAN SENDIRI
B10: Kegiatan | D10: : | E10: Pemeliharaan Sarana dan Prasarana Sekolah
B11: Rincian Kegiatan | D11: : | E11: Pembelian Bahan Kebersihan Sekolah
B12: Kode Rekening | D12: : | E12: Bahan-bahan lainnya
B13: Tahung Anggaran | D13: : | E13: 2026
B16: NO | C16: NAMA BARANG | F16: Volume | H16: Spesifikasi | I16: Harga | J16: Total
B17: 1 | C17: =[1]Sheet1!C24 -> glass cleaner | F17: 15 | G17: =[1]Sheet1!E24 -> liter | H17: =[1]Sheet1!D24 -> cair | I17: =[1]Sheet1!G24 -> 16000 | J17: =F17*I17 -> 240000
B18: 2 | C18: =[1]Sheet1!C25 -> dust cleaner | F18: =[1]Sheet1!F25 -> 3 | G18: =[1]Sheet1!E25 -> galon | H18: =[1]Sheet1!D25 -> cairan minyak pembersih keramik | I18: =[1]Sheet1!G25 -> 185000 | J18: =F18*I18 -> 555000
B19: 3 | C19: =[1]Sheet1!C26 -> karbol | F19: 5 | G19: =[1]Sheet1!E26 -> botol | H19: =[1]Sheet1!D26 -> 800 ml wangi | I19: =[1]Sheet1!G26 -> 23000 | J19: =F19*I19 -> 115000
B20: 4 | C20: =[1]Sheet1!C27 -> sabun cuci piring | F20: =[1]Sheet1!F27 -> 3 | G20: =[1]Sheet1!E27 -> jerigen | H20: =[1]Sheet1!D27 -> 3,7 liter | I20: =[1]Sheet1!G27 -> 79000 | J20: =F20*I20 -> 237000
B21: 5 | C21: =[1]Sheet1!C28 -> pembersih porselin | F21: =[1]Sheet1!F28 -> 3 | G21: =[1]Sheet1!E28 -> galon | H21: =[1]Sheet1!D28 -> isi 4 ltr | I21: =[1]Sheet1!G28 -> 106000 | J21: =F21*I21 -> 318000
B22: 6 | C22: =[1]Sheet1!C29 -> sabun cuci tangan cair | F22: 6 | G22: =[1]Sheet1!E29 -> liter | H22: =[1]Sheet1!D29 -> kemasan botol isi 1 ltr | I22: =[1]Sheet1!G29 -> 45000 | J22: =F22*I22 -> 270000
B23: 7 | C23: =[1]Sheet1!C30 -> kamper | F23: =[1]Sheet1!F30 -> 5 | G23: =[1]Sheet1!E30 -> bungkus | H23: =[1]Sheet1!D30 -> warna | I23: =[1]Sheet1!G30 -> 64000 | J23: =F23*I23 -> 320000
B24: 8 | C24: =[1]Sheet1!C31 -> pengharum kloset | F24: =[1]Sheet1!F31 -> 10 | G24: =[1]Sheet1!E31 -> buah | H24: =[1]Sheet1!D31 -> standar Sni | I24: =[1]Sheet1!G31 -> 23000 | J24: =F24*I24 -> 230000
B25: Jumlah | J25: =SUM(J17:J24) -> 2285000
B26: PPH 22 | J26: =J25*1.5% -> 34275
B27: PPN 11% | J27: =J25*11% -> 251350
B28: Total | J28: =J25+J27 -> 2536350
H31: Jakarta, 2 Juni 2026
B32: Mengetahui,
B33: Kepala Sekolah SDN Kebon Kosong 09 | H33: Bendahara SDN Kebon Kosong 09
B42: Khairunnisa | H42: Tri Wahyuni
B43: NIP. 198402112011012010 | H43: NIP. 196804212016102001

Sheet SPP
A1: PEMERINTAH PROVINSI DAERAH KHUSUS IBUKOTA JAKARTA
A2: DINAS PENDIDIKAN
A3: =HPS!A3 -> SEKOLAH DASAR NEGERI KEBON KOSONG 09
A4: =HPS!A4 -> Jl. Kemayoran Gempol no.32 RT 015.05
C5: =HPS!D5 -> Jakarta Pusat 10630 email :sdnkk05pg@gmail.com
J7: =HPS!H31 -> Jakarta, 2 Juni 2026
B8: Nomor | D8: : | E8: /PK.03.00
B9: Lampiran | D9: : | E9: - | J9: Kepada
B10: Hal | D10: : | E10: Surat Pemintaan Penawaran Harga | I10: Yth : | J10: CV. PUSTAKA CEMERLANG INDONESIA
J11: Di Jakarta
B13: Dengan Hormat,
B15: Berdasarkan Informasi yang kami dapatkan, Perusahaan saudara, CV anda merupakan sebuah penyedia Barang / Jasa dengan harga
B16: yang terjangkau dan kompetitif serta memiliki pelayanan prima. Dalam rangka memenuhi kegiatan Sarana dan Prasarana Sekolah di
B17: SDN Kebon Kosong 09. Maka dengan ini kami meminta CV anda yaitu CV. PUSTAKA CEMERLANG INDONESIA untuk memberikan
B18: penawaran harga sebagai berikut :
B20: No | C20: Nama Barang / Jasa | H20: Kuantitas | J20: Harga
B21: 1 | C21: =HPS!C17 -> glass cleaner | H21: =HPS!F17 -> 15 | I21: =HPS!G17 -> liter
B22: 2 | C22: =HPS!C18 -> dust cleaner | H22: =HPS!F18 -> 3 | I22: =HPS!G18 -> galon
B23: =B22+1 -> 3 | C23: =HPS!C19 -> karbol | H23: =HPS!F19 -> 5 | I23: =HPS!G19 -> botol
B24: =B23+1 -> 4 | C24: =HPS!C20 -> sabun cuci piring | H24: =HPS!F20 -> 3 | I24: =HPS!G20 -> jerigen
B25: =B24+1 -> 5 | C25: =HPS!C21 -> pembersih porselin | H25: =HPS!F21 -> 3 | I25: =HPS!G21 -> galon
B26: =B25+1 -> 6 | C26: =HPS!C22 -> sabun cuci tangan cair | H26: =HPS!F22 -> 6 | I26: =HPS!G22 -> liter
B27: =B26+1 -> 7 | C27: =HPS!C23 -> kamper | H27: =HPS!F23 -> 5 | I27: =HPS!G23 -> bungkus
B28: =B27+1 -> 8 | C28: =HPS!C24 -> pengharum kloset | H28: =HPS!F24 -> 10 | I28: =HPS!G24 -> buah
B31: Di mohon untuk daftar harga tersebut harus kami dapatkan paling lambat 5 (lima) hari kerja dari dibuatnya surat permintaan penawaran ini.
B33: Demikian surat permintan penawaran ini kami sampaikan atas perhatian dan kerjasamanya ucapkan terima kasih.
B35: =HPS!B32 -> Mengetahui,
B36: =HPS!B33 -> Kepala Sekolah SDN Kebon Kosong 09 | J36: =HPS!H33 -> Bendahara SDN Kebon Kosong 09
B45: =HPS!B42 -> Khairunnisa | J45: =HPS!H42 -> Tri Wahyuni
B46: =HPS!B43 -> NIP. 198402112011012010 | J46: =HPS!H43 -> NIP. 196804212016102001

Sheet SURAT PENAWARAN
A8: No | B8: : 04/Offer/PCI/26 | H8: Jakarta, 23 Juni 2025
A9: Lampiran | B9: : -
A10: Hal | B10: : Penawaran Kerjasama
B11: Pengadaan barang dan jasa
A13: Dengan Hormat,
A15: Bersama ini kami CV Pustaka Cemerlang Indonesia Mengajukan surat Penawaran kerjasama pengadaan barang
A16: dan jasa di SDN Kebon Kosong 09 Sebagai penunjang dalam proses KBM ( kegiatan belajar mengajar ), untuk itu kami
A17: sangat berharap agar bisa memesan barang dan jasa yang kami tawarkan, Sebagai bahan pertimbangan berikut
A18: daftar harga yang kami tawarkan :
A20: No | B20: NAMA BARANG | E20: QTY | F20: SATUAN | G20: Harga
A21: 1 | B21: =HPS!C17 -> glass cleaner | E21: =HPS!F17 -> 15 | F21: =HPS!G17 -> liter | G21: =HPS!J17+5000 -> 245000
A22: 2 | B22: =HPS!C18 -> dust cleaner | E22: =HPS!F18 -> 3 | F22: =HPS!G18 -> galon | G22: =HPS!J18+5000 -> 560000
A23: 3 | B23: =HPS!C19 -> karbol | E23: =HPS!F19 -> 5 | F23: =HPS!G19 -> botol | G23: =HPS!J19+5000 -> 120000
A24: 4 | B24: =HPS!C20 -> sabun cuci piring | E24: =HPS!F20 -> 3 | F24: =HPS!G20 -> jerigen | G24: =HPS!J20+5000 -> 242000
A25: =A24+1 -> 5 | B25: =HPS!C21 -> pembersih porselin | E25: =HPS!F21 -> 3 | F25: =HPS!G21 -> galon | G25: =HPS!J21+5000 -> 323000
A26: =A25+1 -> 6 | B26: =HPS!C22 -> sabun cuci tangan cair | E26: =HPS!F22 -> 6 | F26: =HPS!G22 -> liter | G26: =HPS!J22+5000 -> 275000
A27: =A26+1 -> 7 | B27: =HPS!C23 -> kamper | E27: =HPS!F23 -> 5 | F27: =HPS!G23 -> bungkus | G27: =HPS!J23+5000 -> 325000
A28: =A27+1 -> 8 | B28: =HPS!C24 -> pengharum kloset | E28: =HPS!F24 -> 10 | F28: =HPS!G24 -> buah | G28: =HPS!J24+5000 -> 235000
A31: Demikian surat penawaran kerjasama ini kami ajuka, atas perhatian dan kerjasamanya kami ucapkan terima kasih.
A33: Hormat kami,
A38: Bambang Solifian

Sheet SURAT NEGOSIASI (2)
D1: =[2]SPP!$E$1 -> PEMERINTAH PROVINSI DAERAH KHUSUS IBUKOTA JAKARTA
D2: =[2]SPP!$E$2 -> DINAS PENDIDIKAN
D3: =HPS!$A$3 -> SEKOLAH DASAR NEGERI KEBON KOSONG 09
D4: =HPS!$A$4 -> Jl. Kemayoran Gempol no.32 RT 015.05
D5: =HPS!$D$5 -> Jakarta Pusat 10630 email :sdnkk05pg@gmail.com
B9: BERITA ACARA NEGOSIASI HARGA
B10: Nomor : /PK.03.00
B12: Pada Hari ini, Rabu Tanggal Dua Puluh Empat Bulan Juni Tahun Dua Ribu Dua Puluh enam
B13: Yang bertanda tangan dibawah ini :
B14: Nama | C14: : | D14: =HPS!H42 -> Tri Wahyuni
B15: Jabatan | C15: : | D15: Bendahara SDN Kebon Kosong 09
B16: Nip | C16: : | D16: 196804212016102001
B17: Instansi | C17: : | D17: SDN Kebon Kosong 09
B18: Alamat | D18: Jl. Kemayoran Gempol no.32
B20: Dalam hal ini bertindak untuk dan atas nama Sekolah, Selanjutnya disebut sebagai PIHAK PERTAMA,
B22: Nama | C22: : | D22: Bambang Solifian
B23: Jabatan | C23: : | D23: Direktur
B24: Perusahaan | C24: : | D24: CV. PUSTAKA CEMERLANG INDONESIA
B25: Alamat | C25: : | D25: Wisma Mitra Sunter 3-03
D26: Jl. Yos Sudarso Kav. 89, Boulevard Mitra Sunter Blok C2, Sunter Jaya, Tanjung Priok
B28: Dalam hal bertindak untuk dan atas nama CV. PUSTAKA CEMERLANG INDONESIA, disebut sebagai PIHAK KEDUA,
B30: Berdasarkan Surat Penawaran yang disampaikan CV. PUSTAKA CEMERLANG INDONESIA, maka kedua belah pihak bersepakat untuk melakukan negosiasi harga atas penawaran tersebtu. Adapun penawaran harga tersebut sebagai berikut :
B32: Harga yang ditawarkan
B33: No | C33: Nama Barang / Jasa | E33: Kuantitas | G33: Spesifikasi | H33: Harga Pihak Kedua
B34: =[2]HPS!B17 -> 1 | C34: =HPS!C17 -> glass cleaner | E34: =HPS!F17 -> 15 | F34: =HPS!G17 -> liter | G34: =HPS!H17 -> cair | H34: ='SURAT PENAWARAN'!G21 -> 245000
B35: =[2]HPS!B18 -> 2 | C35: =HPS!C18 -> dust cleaner | E35: =HPS!F18 -> 3 | F35: =HPS!G18 -> galon | G35: =HPS!H18 -> cairan minyak pembersih keramik | H35: ='SURAT PENAWARAN'!G22 -> 560000
B36: =[2]HPS!B19 -> 3 | C36: =HPS!C19 -> karbol | E36: =HPS!F19 -> 5 | F36: =HPS!G19 -> botol | G36: =HPS!H19 -> 800 ml wangi | H36: ='SURAT PENAWARAN'!G23 -> 120000
B37: 4 | C37: =HPS!C20 -> sabun cuci piring | E37: =HPS!F20 -> 3 | F37: =HPS!G20 -> jerigen | G37: =HPS!H20 -> 3,7 liter | H37: ='SURAT PENAWARAN'!G24 -> 242000
B38: 5 | C38: =HPS!C21 -> pembersih porselin | E38: =HPS!F21 -> 3 | F38: =HPS!G21 -> galon | G38: =HPS!H21 -> isi 4 ltr | H38: ='SURAT PENAWARAN'!G25 -> 323000
B39: 6 | C39: =HPS!C22 -> sabun cuci tangan cair | E39: =HPS!F22 -> 6 | F39: =HPS!G22 -> liter | G39: =HPS!H22 -> kemasan botol isi 1 ltr | H39: ='SURAT PENAWARAN'!G26 -> 275000
B40: 7 | C40: =HPS!C23 -> kamper | E40: =HPS!F23 -> 5 | F40: =HPS!G23 -> bungkus | G40: =HPS!H23 -> warna | H40: ='SURAT PENAWARAN'!G27 -> 325000
B41: 8 | C41: =HPS!C24 -> pengharum kloset | E41: =HPS!F24 -> 10 | F41: =HPS!G24 -> buah | G41: =HPS!H24 -> standar Sni | H41: ='SURAT PENAWARAN'!G28 -> 235000
B43: Harga Negosiasi
B44: No | C44: Nama Barang / Jasa | E44: Kuantitas | G44: Spesifikasi | H44: Harga Negosiasi
B45: =B34 -> 1 | C45: =C34 -> glass cleaner | E45: =E34 -> 15 | F45: =F34 -> liter | G45: =G34 -> cair | H45: =HPS!J17 -> 240000
B46: =B35 -> 2 | C46: =C35 -> dust cleaner | E46: =E35 -> 3 | F46: =F35 -> galon | G46: =G35 -> cairan minyak pembersih keramik | H46: =HPS!J18 -> 555000
B47: =B36 -> 3 | C47: =C36 -> karbol | E47: =E36 -> 5 | F47: =F36 -> botol | G47: =G36 -> 800 ml wangi | H47: =HPS!J19 -> 115000
B48: 4 | C48: =C37 -> sabun cuci piring | E48: =E37 -> 3 | F48: =F37 -> jerigen | G48: =G37 -> 3,7 liter | H48: =HPS!J20 -> 237000
B49: 5 | C49: =C38 -> pembersih porselin | E49: =E38 -> 3 | F49: =F38 -> galon | G49: =G38 -> isi 4 ltr | H49: =HPS!J21 -> 318000
B50: 6 | C50: =C39 -> sabun cuci tangan cair | E50: =E39 -> 6 | F50: =F39 -> liter | G50: =G39 -> kemasan botol isi 1 ltr | H50: =HPS!J22 -> 270000
...

Sheet SURAT PESANAN (2)
D1: ='[2]SURAT NEGOSIASI'!D1 -> PEMERINTAH PROVINSI DAERAH KHUSUS IBUKOTA JAKARTA | M1: =D1 -> PEMERINTAH PROVINSI DAERAH KHUSUS IBUKOTA JAKARTA
D2: ='[2]SURAT NEGOSIASI'!D2 -> DINAS PENDIDIKAN | M2: =D2 -> DINAS PENDIDIKAN
E3: =SPP!A3 -> SEKOLAH DASAR NEGERI KEBON KOSONG 09 | M3: =E3 -> SEKOLAH DASAR NEGERI KEBON KOSONG 09
E4: =HPS!A4 -> Jl. Kemayoran Gempol no.32 RT 015.05 | M4: =E4 -> Jl. Kemayoran Gempol no.32 RT 015.05
A9: SURAT PESANAN | K9: Nomor : | L9: /PK.03.00 | Q9: Jakarta, | R9: =J61 -> 46198
A10: Nomor : | G10: /PK.03.00 | K10: Lampiran : | L10: - | Q10: Kepada,
K11: Perihal : | L11: Surat Pesanan | Q11: Yth. CV. Pustaka Cemerlang Indonesia
B12: Kegiatan : | E12: =HPS!E10 -> Pemeliharaan Sarana dan Prasarana Sekolah | Q12: Di
B13: Rincian Kegiatan : | E13: =HPS!E12 -> Bahan-bahan lainnya | R13: Tempat
B14: Kode Rekening : | E14: =HPS!E13 -> 2026
K15: Berdasarkan Berita acara hasil negosiasi nomor | P15: =G10 -> /PK.03.00 | R15: Tanggal | S15: =J39 -> 46198
B16: Yang bertanda tangan di bawah ini | K16: bersama ini mengajukan pesanan kebutuhan kegiatan | Q16: =E13 -> Bahan-bahan lainnya
C17: Nama : | E17: =HPS!$B$42 -> Khairunnisa | K17: dengan rincian sebagai berikut :
C18: Jabatan : | E18: Kepala Sekolah SDN Kebon Kosong 09
C19: Alamat : | E19: ='SURAT NEGOSIASI (2)'!$D$18 -> Jl. Kemayoran Gempol no.32 | K19: No | L19: Uraian | O19: Volume | Q19: Satuan | R19: Harga Satuan | S19: Jumlah
B20: Selanjutnya disebut Pengguna Anggaran | K20: =[2]HPS!B17 -> 1 | L20: =[2]HPS!C17 -> Kamper | O20: =[2]HPS!F17 -> 3 | Q20: =[2]HPS!G17 -> bks | R20: =[2]HPS!I17 -> 33000 | S20: =O20*R20 -> 99000
K21: Sub Total | S21: =SUM(S20:S20) -> 99000
C22: Nama : | E22: Bambang Solifian | K22: PPN 11% | S22: =S21*0.11 -> 10890
C23: Jabatan : | E23: ='[3]SURAT NEGOSIASI'!C23 -> Direktur Utama | K23: PPH 22 | S23: =S21*0.015 -> 1485
C24: Alamat : | E24: ='[2]SURAT NEGOSIASI'!D26 -> Jl. Yos Sudarso Kav. 89, Boulevard Mitra Sunter Blok C2, Sunter Jaya, Tanjung Priok | K24: PPH 23 | S24: 0
K25: Total | S25: =SUM(S21:S24) -> 111375
B26: Selanjutnya disebut Penyedia Jasa
K27: Demikian surat pesanan ini, atas kerja samanya diucapkan terima kasih
B28: Untuk mengerjakan kegiatan Belanja Alat/Bahan | H28: =E12 -> Pemeliharaan Sarana dan Prasarana Sekolah
B29: Pada kegiatan | E29: =E13 -> Bahan-bahan lainnya | F29: dengan memerhatikan ketentuan-ketentuan | R29: =I41 -> Kepala Sekolah
B30: sebagai berikut: | R30: =I42 -> SDN Kebon Kosong 13,
A31: 1. | B31: Rincian Pekerjaan (terlampir)
A32: 2. | B32: Syarat-syarat pekerjaan; sesuai dengan persyaratan dan ketentuan yang berlaku
A33: 3. | B33: Waktu pelaksanaan
A34: 4. | B34: Pembayaran; Pembayaran dilakukan setelah penyelesaian pekerjaan, Denda, terhadap setiap
B35: hari keterlambatan penyelesaian pekerjaan, penyedia jasa akan dikenakan denda keterlambatan
B36: 1% dari nilai pesanan atau bagian tetentu dari nilai pesanan sesuai dengan persyaratan dan | R36: =I48 -> Khairunnisa
B37: ketentuan yang berlaku. | R37: =I49 -> NIP. 198402112011012010
I39: Jakarta, | J39: 46198
B40: Menerima dan Meyetujui | I40: Pengguna Anggaran
B41: Untuk dan atas nama | I41: Kepala Sekolah
B42: CV. Pustaka Cemerlang Indonesia, | I42: SDN Kebon Kosong 13,
B48: Bambang Solifian | I48: =HPS!B42 -> Khairunnisa
B49: ='[3]SURAT NEGOSIASI'!C23 -> Direktur Utama | I49: =HPS!B43 -> NIP. 198402112011012010
I59: Lampiran : | J59: SURAT PESANAN
...

Sheet FAKTUR
L2: SALES INVOICE
L3: Invoice Date : | N3: Invoice No :
L4: =N6 -> 46189 | N4: 4/PCI/KK09/2026
L5: Terms : | N5: Ship Date :
L6: Net 90 | N6: 46189
A7: Bill To | B7: : | C7: =HPS!A3 -> SEKOLAH DASAR NEGERI KEBON KOSONG 09 | L7: Ship Via : | N7: Currency :
L8: Mobil Box | N8: IDR
A9: Ship To | B9: : | C9: =C7 -> SEKOLAH DASAR NEGERI KEBON KOSONG 09
C10: =HPS!A4 -> Jl. Kemayoran Gempol no.32 RT 015.05
A12: Item | E12: Qty | F12: Unit Price | H12: Total | J12: PPN | L12: PPH 22 | M12: PPH 23 | N12: Amount
A13: =HPS!C17 -> glass cleaner | E13: =HPS!F17 -> 15 | F13: =HPS!I17 -> 16000 | H13: =E13*F13 -> 240000 | J13: =H13*11% -> 26400 | L13: =H13*1.5% -> 3600 | N13: =HPS!J17 -> 240000
A14: =HPS!C18 -> dust cleaner | E14: =HPS!F18 -> 3 | F14: =HPS!I18 -> 185000 | H14: =E14*F14 -> 555000 | J14: =H14*11% -> 61050 | L14: =H14*1.5% -> 8325 | N14: =HPS!J18 -> 555000
A15: =HPS!C19 -> karbol | E15: =HPS!F19 -> 5 | F15: =HPS!I19 -> 23000 | H15: =E15*F15 -> 115000 | J15: =H15*11% -> 12650 | L15: =H15*1.5% -> 1725 | N15: =HPS!J19 -> 115000
A16: =HPS!C20 -> sabun cuci piring | E16: =HPS!F20 -> 3 | F16: =HPS!I20 -> 79000 | H16: =E16*F16 -> 237000 | J16: =H16*11% -> 26070 | L16: =H16*1.5% -> 3555 | N16: =HPS!J20 -> 237000
A17: =HPS!C21 -> pembersih porselin | E17: =HPS!F21 -> 3 | F17: =HPS!I21 -> 106000 | H17: =E17*F17 -> 318000 | J17: =H17*11% -> 34980 | L17: =H17*1.5% -> 4770 | N17: =HPS!J21 -> 318000
A18: =HPS!C22 -> sabun cuci tangan cair | E18: =HPS!F22 -> 6 | F18: =HPS!I22 -> 45000 | H18: =E18*F18 -> 270000 | J18: =H18*11% -> 29700 | L18: =H18*1.5% -> 4050 | N18: =HPS!J22 -> 270000
A19: =HPS!C23 -> kamper | E19: =HPS!F23 -> 5 | F19: =HPS!I23 -> 64000 | H19: =E19*F19 -> 320000 | J19: =H19*11% -> 35200 | L19: =H19*1.5% -> 4800 | N19: =HPS!J23 -> 320000
A20: =HPS!C24 -> pengharum kloset | E20: =HPS!F24 -> 10 | F20: =HPS!I24 -> 23000 | H20: =E20*F20 -> 230000 | J20: =H20*11% -> 25300 | L20: =H20*1.5% -> 3450 | N20: =HPS!J24 -> 230000
A22: Total | H22: =SUM(H13:I21) -> 2285000 | J22: =HPS!J27 -> 251350 | L22: =HPS!J26 -> 34275 | N22: =HPS!J28 -> 2536350
A23: Say | B23: : | C23: =PROPER(IF(N22=0,"nol",IF(N22<0,"minus ","")& SUBSTITUTE(TRIM(SUBSTITUTE(SUBSTITUTE(SUBSTITUTE(SUBSTITUTE(SUBSTITUTE(SUBSTITUTE(SUBSTITUTE(SUBSTITUTE(SUBSTITUTE(SUBSTITUTE(SUBSTITUTE(SUBSTITUTE(SUBSTITUTE(SUBSTITUTE(SUBSTITUTE(SUBSTITUTE(SUBSTITUTE(SUBSTITUTE(SUBSTITUTE(SUBSTITUTE(SUBSTITUTE(SUBSTITUTE(SUBSTITUTE(SUBSTITUTE( IF(--MID(TEXT(ABS(N22),"000000000000000"),1,3)=0,"",MID(TEXT(ABS(N22),"000000000000000"),1,1)&" ratus "&MID(TEXT(ABS(N22),"000000000000000"),2,1)&" puluh "&MID(TEXT(ABS(N22),"000000000000000"),3,1)&" trilyun ")& IF(--MID(TEXT(ABS(N22),"000000000000000"),4,3)=0,"",MID(TEXT(ABS(N22),"000000000000000"),4,1)&" ratus "&MID(TEXT(ABS(N22),"000000000000000"),5,1)&" puluh "&MID(TEXT(ABS(N22),"000000000000000"),6,1)&" milyar ")& IF(--MID(TEXT(ABS(N22),"000000000000000"),7,3)=0,"",MID(TEXT(ABS(N22),"000000000000000"),7,1)&" ratus "&MID(TEXT(ABS(N22),"000000000000000"),8,1)&" puluh "&MID(TEXT(ABS(N22),"000000000000000"),9,1)&" juta ")& IF(--MID(TEXT(ABS(N22),"000000000000000"),10,3)=0,"",IF(--MID(TEXT(ABS(N22),"000000000000000"),10,3)=1,"*",MID(TEXT(ABS(N22),"000000000000000"),10,1)&" ratus "&MID(TEXT(ABS(N22),"000000000000000"),11,1)&" puluh ")&MID(TEXT(ABS(N22),"000000000000000"),12,1)&" ribu ")& IF(--MID(TEXT(ABS(N22),"000000000000000"),13,3)=0,"",MID(TEXT(ABS(N22),"000000000000000"),13,1)&" ratus "&MID(TEXT(ABS(N22),"000000000000000"),14,1)&" puluh "&MID(TEXT(ABS(N22),"000000000000000"),15,1)),1,"satu"),2,"dua"),3,"tiga"),4,"empat"),5,"lima"),6,"enam"),7,"tujuh"),8,"delapan"),9,"sembilan"),"0 ratus",""),"0 puluh",""),"satu puluh 0","sepuluh"),"satu puluh satu","sebelas"),"satu puluh dua","duabelas"),"satu puluh tiga","tigabelas"),"satu puluh empat","empatbelas"),"satu puluh lima","limabelas"),"satu puluh enam","enambelas"),"satu puluh tujuh","tujuhbelas"),"satu puluh delapan","delapanbelas"),"satu puluh sembilan","sembilanbelas"),"satu ratus","seratus"),"*satu ribu","seribu"),0,""))," "," "))&" Rupiah") -> Dua Juta Lima Ratus Tiga Puluh Enam Ribu Tiga Ratus Lima Puluh Rupiah
A25: Approved By | K25: Received By
A30: Bambang Solifian

Sheet KWITANSI
C3: CV. PUSTAKA CEMERLANG INDONESIA
C4: Wisma Mitra Sunter Unit 3-03, Jl. Yos Sudarso KAV.89,
C5: BOULEVARD MITRA SUNTER BLOK C2, Kel. Sunter Jaya
C6: Email : cv.pustakacemerlangindonesia@gmail.com
A8: KWITANSI
B9: No | C9: : 4/KW-PCI/KK09/2026
B10: Telah diterima dari :
B11: Dinas Pendidikan Provinsi DKI Jakarta"Cq.SDN Kebon Kosong 09"
B13: Terbilang :
B14: =FAKTUR!C23 -> Dua Juta Lima Ratus Tiga Puluh Enam Ribu Tiga Ratus Lima Puluh Rupiah
B17: Untuk Pembayaran :
B18: =HPS!E10 -> Pemeliharaan Sarana dan Prasarana Sekolah
B20: Jumlah :
B21: =FAKTUR!N22 -> 2536350 | E21: Jakarta, 17 Oktober 2025
D28: =FAKTUR!A30 -> Bambang Solifian

Sheet SURAT JALAN
J2: SURAT JALAN
J3: Invoice Date : | L3: Delivery No :
J4: =FAKTUR!L4 -> 46189 | L4: 5/DO/PCI/2026
J5: Terms : | L5: Ship Date :
J6: Net 90 | L6: =FAKTUR!N6 -> 46189
J7: Ship Via : | L7: Currency :
A8: Ship To | B8: : | C8: Sekolah Dasar Negeri Kebon Kosong 09 | J8: Mobil Box | L8: IDR
C10: Jl Kemayoran Gempol no.32
A12: BARANG | E12: Qty | F12: SATUAN | H12: Spesifikasi | I12: Harga | J12: Jumlah | K12: PPN | L12: Total
A13: =FAKTUR!A13 -> glass cleaner | E13: =FAKTUR!E13 -> 15 | F13: =HPS!G17 -> liter | H13: =HPS!H17 -> cair | I13: =HPS!I17 -> 16000 | J13: =I13*E13 -> 240000 | K13: =J13*0.1 -> 24000 | L13: =HPS!J17 -> 240000
A14: =FAKTUR!A14 -> dust cleaner | E14: =FAKTUR!E14 -> 3 | F14: =HPS!G18 -> galon | H14: =HPS!H18 -> cairan minyak pembersih keramik | I14: =HPS!I18 -> 185000 | J14: =I14*E14 -> 555000 | L14: =HPS!J18 -> 555000
A15: =FAKTUR!A15 -> karbol | E15: =FAKTUR!E15 -> 5 | F15: =HPS!G19 -> botol | H15: =HPS!H19 -> 800 ml wangi | I15: =HPS!I19 -> 23000 | J15: =I15*E15 -> 115000 | L15: =HPS!J19 -> 115000
A16: =FAKTUR!A16 -> sabun cuci piring | E16: =FAKTUR!E16 -> 3 | F16: =HPS!G20 -> jerigen | H16: =HPS!H20 -> 3,7 liter | I16: =HPS!I20 -> 79000 | J16: =I16*E16 -> 237000 | L16: =HPS!J20 -> 237000
A17: =FAKTUR!A17 -> pembersih porselin | E17: =FAKTUR!E17 -> 3 | F17: =HPS!G21 -> galon | H17: =HPS!H21 -> isi 4 ltr | I17: =HPS!I21 -> 106000 | J17: =I17*E17 -> 318000 | L17: =HPS!J21 -> 318000
A18: =FAKTUR!A18 -> sabun cuci tangan cair | E18: =FAKTUR!E18 -> 6 | F18: =HPS!G22 -> liter | H18: =HPS!H22 -> kemasan botol isi 1 ltr | I18: =HPS!I22 -> 45000 | J18: =I18*E18 -> 270000 | L18: =HPS!J22 -> 270000
A19: =FAKTUR!A19 -> kamper | E19: =FAKTUR!E19 -> 5 | F19: =HPS!G23 -> bungkus | H19: =HPS!H23 -> warna | I19: =HPS!I23 -> 64000 | J19: =I19*E19 -> 320000 | L19: =HPS!J23 -> 320000
A20: =FAKTUR!A20 -> pengharum kloset | E20: =FAKTUR!E20 -> 10 | F20: =HPS!G24 -> buah | H20: =HPS!H24 -> standar Sni | I20: =HPS!I24 -> 23000 | J20: =I20*E20 -> 230000 | L20: =HPS!J24 -> 230000
A22: Delivered By | I22: Received By

Sheet BAPB
A1: PEMERINTAH PROVINSI DAERAH KHUSUS IBUKOTA JAKARTA
A2: =HPS!A2 -> DINAS PENDIDIKAN
A3: =HPS!A3 -> SEKOLAH DASAR NEGERI KEBON KOSONG 09
A4: =HPS!A4 -> Jl. Kemayoran Gempol no.32 RT 015.05
D6: =HPS!D5 -> Jakarta Pusat 10630 email :sdnkk05pg@gmail.com
A8: BERITA ACARA PEMERIKSAAN BARANG
A9: No : /PK.03.00
B11: Pada hari ini, Selasa Tanggal Enam Belas bulan Juni Tahun Dua Ribu Dua Puluh Enam yang bertanda tangan dibawah ini :
B12: Nama | C12: : | D12: Sulistiawati
B13: Jabatan | C13: : | D13: Pengurus Barang
B14: NIP | C14: : | D14: 197909092022212008
B15: Instansi | C15: : | D15: ='SURAT NEGOSIASI (2)'!$D$17 -> SDN Kebon Kosong 09
B16: Alamat | C16: : | D16: ='SURAT NEGOSIASI (2)'!$D$18 -> Jl. Kemayoran Gempol no.32
B18: Dalam hal ini bertindak untuk dan atas nama Sekolah, Selanjutnya disebut sebagai PIHAK PERTAMA,
B20: Nama | C20: : | D20: ='SURAT NEGOSIASI (2)'!$D$22 -> Bambang Solifian
B21: Jabatan | C21: : | D21: ='SURAT NEGOSIASI (2)'!$D$23 -> Direktur
B22: Perusahaan | C22: : | D22: ='SURAT NEGOSIASI (2)'!$D$24 -> CV. PUSTAKA CEMERLANG INDONESIA
B23: Alamat | C23: : | D23: ='SURAT NEGOSIASI (2)'!$D$25 -> Wisma Mitra Sunter 3-03
D24: ='SURAT NEGOSIASI (2)'!$D$26 -> Jl. Yos Sudarso Kav. 89, Boulevard Mitra Sunter Blok C2, Sunter Jaya, Tanjung Priok
B26: Dalam hal ini bertindak untuk dan atas nama CV. PUSTAKA CEMERLANG INDONESIA, Selanjutnya disebut sebagai
B27: PIHAK KEDUA,
B28: Bahwa sehubungan pekerjaan pengadaan barang / jasa dengan Pihak Kedua. Setelah dilakukan pemeriksaan oleh
B29: Pihak Pertama dengan ini menyatakan sebagai berikut :
B31: No | C31: Nama Barang / Jasa | G31: Kuantitas | I31: Kondisi Barang
B32: 1 | C32: =HPS!C17 -> glass cleaner | G32: =HPS!F17 -> 15 | H32: =HPS!G17 -> liter | I32: Baik
B33: 2 | C33: =HPS!C18 -> dust cleaner | G33: =HPS!F18 -> 3 | H33: =HPS!G18 -> galon | I33: Baik
B34: 3 | C34: =HPS!C19 -> karbol | G34: =HPS!F19 -> 5 | H34: =HPS!G19 -> botol | I34: Baik
B35: 4 | C35: =HPS!C20 -> sabun cuci piring | G35: =HPS!F20 -> 3 | H35: =HPS!G20 -> jerigen | I35: Baik
B36: 5 | C36: =HPS!C21 -> pembersih porselin | G36: =HPS!F21 -> 3 | H36: =HPS!G21 -> galon | I36: Baik
B37: 6 | C37: =HPS!C22 -> sabun cuci tangan cair | G37: =HPS!F22 -> 6 | H37: =HPS!G22 -> liter | I37: Baik
B38: 7 | C38: =HPS!C23 -> kamper | G38: =HPS!F23 -> 5 | H38: =HPS!G23 -> bungkus | I38: Baik
B39: 8 | C39: =HPS!C24 -> pengharum kloset | G39: =HPS!F24 -> 10 | H39: =HPS!G24 -> buah | I39: Baik
B41: Demikian Berita Acara Pemeriksaan Hasil Pekerjaan ini dibuat dengan sebenarnya dan dipergunakan semestinya.
B43: PIHAK PERTAMA | I43: PIHAK KEDUA
B49: =D12 -> Sulistiawati | I49: =D20 -> Bambang Solifian
B50: NIP. 197909092022212008
F53: =HPS!B32 -> Mengetahui,
F54: =HPS!B33 -> Kepala Sekolah SDN Kebon Kosong 09
F60: =HPS!$B$42 -> Khairunnisa
F61: =HPS!$B$43 -> NIP. 198402112011012010

Sheet BAST
A1: PEMERINTAH PROVINSI DAERAH KHUSUS IBUKOTA JAKARTA
A2: DINAS PENDIDIKAN
A3: =[4]BAPB!A4 -> SEKOLAH DASAR NEGERI KEBON KOSONG 09 PAGI
A4: =HPS!A4 -> Jl. Kemayoran Gempol no.32 RT 015.05
A8: BERITA ACARA SERAH TERIMA BARANG
A9: No : /PK.03.00
B11: =BAPB!B11 -> Pada hari ini, Selasa Tanggal Enam Belas bulan Juni Tahun Dua Ribu Dua Puluh Enam yang bertanda tangan dibawah ini :
B12: Nama | C12: : | D12: =BAPB!D12 -> Sulistiawati
B13: Jabatan | C13: : | D13: =BAPB!D13 -> Pengurus Barang
B14: NIP | C14: : | D14: 197909092022212008
B15: Nama Sekolah | C15: : | D15: =BAPB!D15 -> SDN Kebon Kosong 09
B16: Alamat | C16: : | D16: =BAPB!D16 -> Jl. Kemayoran Gempol no.32
B18: Dalam hal ini bertindak untuk dan atas nama Sekolah, Selanjutnya disebut sebagai PIHAK PERTAMA,
B20: Nama | C20: : | D20: =BAPB!D20 -> Bambang Solifian
B21: Jabatan | C21: : | D21: =BAPB!D21 -> Direktur
B22: Perusahaan | C22: : | D22: =BAPB!D22 -> CV. PUSTAKA CEMERLANG INDONESIA
B23: Instansi | C23: : | D23: =BAPB!D23 -> Wisma Mitra Sunter 3-03
B24: Alamat | C24: : | D24: =BAPB!D24 -> Jl. Yos Sudarso Kav. 89, Boulevard Mitra Sunter Blok C2, Sunter Jaya, Tanjung Priok
B26: Dalam hal ini bertindak untuk dan atas nama CV. MITRA KARYA GEMILANG, Selanjutnya disebut sebagai PIHAK KEDUA,
B28: Dengan ini PIHAK PERTAMA telah menyerahkan kepada PIHAK KEDUA, dan PIHAK KEDUA telah menerima
B29: penyerahan barang dari PIHAK PERTAMA dalam jumlah yang lengkap dan kondisi yang baik, dengan rincian:
B31: No | C31: NAMA BARANG | G31: QTY | H31: SATUAN | I31: Kondisi Barang
B32: 1 | C32: =BAPB!C32 -> glass cleaner | G32: =BAPB!G32 -> 15 | H32: =BAPB!H32 -> liter | I32: Baik
B33: 2 | C33: =BAPB!C33 -> dust cleaner | G33: =BAPB!G33 -> 3 | H33: =BAPB!H33 -> galon | I33: Baik
B34: 3 | C34: =BAPB!C34 -> karbol | G34: =BAPB!G34 -> 5 | H34: =BAPB!H34 -> botol | I34: Baik
B35: 4 | C35: =BAPB!C35 -> sabun cuci piring | G35: =BAPB!G35 -> 3 | H35: =BAPB!H35 -> jerigen | I35: Baik
B36: 5 | C36: =BAPB!C36 -> pembersih porselin | G36: =BAPB!G36 -> 3 | H36: =BAPB!H36 -> galon | I36: Baik
B37: 6 | C37: =BAPB!C37 -> sabun cuci tangan cair | G37: =BAPB!G37 -> 6 | H37: =BAPB!H37 -> liter | I37: Baik
B38: 7 | C38: =BAPB!C38 -> kamper | G38: =BAPB!G38 -> 5 | H38: =BAPB!H38 -> bungkus | I38: Baik
B39: 8 | C39: =BAPB!C39 -> pengharum kloset | G39: =BAPB!G39 -> 10 | H39: =BAPB!H39 -> buah | I39: Baik
B42: Dengan adanya berita Acara Serah Terima barang ini maka Pekerjaan PIHAK KEDUA telah selesai melaksanakan
B43: kewajibannya dengan baik dan berhak menerima pembayaran dari PIHAK PERTAMA.
B45: Demikian Berita Acara Serah Terima ini dibuat untuk dapat dipergunakan sebagaimana mestinya.
B47: Yang Menyerahkan, | J47: Yang Menerima,
B48: PIHAK PERTAMA | J48: PIHAK KEDUA
B53: =D12 -> Sulistiawati | J53: =BAPB!I49 -> Bambang Solifian
B54: =BAPB!B50 -> NIP. 197909092022212008
E56: ='[4]SURAT NEGOSIASI'!E52:J52 -> Mengetahui,
E57: ='[4]SURAT NEGOSIASI'!E53:J53 -> Kepala Sekolah
E62: =BAPB!F60 -> Khairunnisa
...

Sheet BAPP
A1: PEMERINTAH PROVINSI DAERAH KHUSUS IBUKOTA JAKARTA
A2: DINAS PENDIDIKAN
A3: =[4]BAPB!A4 -> SEKOLAH DASAR NEGERI KEBON KOSONG 09 PAGI
A4: =HPS!A4 -> Jl. Kemayoran Gempol no.32 RT 015.05
A9: BERITA ACARA PENYELESAIAN PEKERJAAN
F10: Nomor : | H10: /PK.03.00
B12: =BAST!B11 -> Pada hari ini, Selasa Tanggal Enam Belas bulan Juni Tahun Dua Ribu Dua Puluh Enam yang bertanda tangan dibawah ini :
B15: =[2]BAST!B14 -> Nama | C15: =[2]BAPB!C23 -> : | D15: Bambang Solifian
B16: =[2]BAST!B15 -> Jabatan | C16: =[2]BAPB!C24 -> : | D16: =[2]BAST!D15 -> Direktur Utama
B17: =[2]BAPB!B25 -> Alamat | C17: =[2]BAPB!C25 -> : | D17: =[2]BAPB!D25 -> Wisma Mitra Sunter 3-03
D18: =[2]BAPB!D26 -> Jl. Yos Sudarso Kav. 89, Boulevard Mitra Sunter Blok C2, Sunter Jaya, Tanjung Priok
B20: Dalam hal ini bertindak untuk dan atas nama Sekolah, Selanjutnya disebut sebagai PIHAK PERTAMA,
B22: =[2]BAST!B22 -> Nama | C22: : | D22: =BAST!D12 -> Sulistiawati
B23: =[2]BAST!B23 -> Jabatan | C23: : | D23: =BAST!D13 -> Pengurus Barang
B24: =[2]BAST!B24 -> NIP | C24: : | D24: =BAST!D14 -> 197909092022212008
B25: =[2]BAST!B25 -> Instansi | C25: : | D25: =BAST!D15 -> SDN Kebon Kosong 09
B26: =[2]BAST!B26 -> Alamat | C26: : | D26: =BAST!D16 -> Jl. Kemayoran Gempol no.32
B28: Dalam hal ini bertindak untuk dan atas nama CV. MITRA KARYA GEMILANG, Selanjutnya disebut sebagai PIHAK KEDUA,
B30: Berdasarkan | D30: :
B31: 1. | C31: Surat Pesanan | E31: ='[2]SURAT PESANAN'!L9 -> /PK.03.00 | H31: Tanggal | I31: ='SURAT PESANAN (2)'!J39 -> 46198
B32: 2. | C32: Berita Acara Serah Terima Hasil Pekerjaan | H32: =BAST!A9 -> No : /PK.03.00 | J32: Tanggal | K32: =FAKTUR!N6 -> 46189
B34: Dengan ini menyatakan bahwa PIHAK PERTAMA telah melaksanakan penyelesaian pekerjaan Belanja Alat/bahan untuk
B35: Kegiatan | C35: ='[2]SURAT PESANAN'!E63 -> Pembelian Alat Kebersihan Maret | F35: mencapai 100% dan dinyatakan oleh PIHAK KEDUA telah memenuhi ketentuan
B36: dalam kontrak dengan hasil pekerjaan dalam keadaan BAIK
C38: Demikian Berita Acara Penyelesaian Pekerjaan ini dibuat dan ditandatangani oleh kedua belah pihak
B40: PIHAK KEDUA | J40: PIHAK PERTAMA,
B41: PENGGUNA ANGGARAN | J41: CV. Pustaka Cemerlang Indonesia
B42: Kepala | C42: =D25 -> SDN Kebon Kosong 09 | J42: =[2]BAST!B58 -> Direktur Utama
B48: ='SURAT PESANAN (2)'!I48 -> Khairunnisa | J48: =BAST!J53 -> Bambang Solifian
B49: ='SURAT PESANAN (2)'!I49 -> NIP. 198402112011012010

Sheet Lamp BAPP
H2: Lampiran | I2: : | J2: Berita Acara Penyelesaian Pekerjaan
H3: Nomor | I3: : | J3: =BAPP!H10 -> /PK.03.00
H4: Tanggal | I4: : | J4: =FAKTUR!L4 -> 46189
A6: RINCIAN HARGA
A7: Belanja Alat/Bahan Untuk Kegiatan | G7: ='[2]SURAT PESANAN'!E12 -> Pembelian Alat Kebersihan Maret
A9: NO | B9: Uraian | E9: Volume | F9: Harga | H9: Jumlah | K9: Kondisi | M9: Keterangan
A10: 1 | B10: 2 | E10: 3 | F10: 4 | H10: 5 | K10: Baik | L10: Tidak Baik
A11: =[2]BAST!B33 -> 1 | B11: =HPS!C17 -> glass cleaner | E11: =HPS!F17 -> 15 | F11: =HPS!I17 -> 16000 | H11: =E11*F11 -> 240000 | K11: √
A12: 2
A13: 3
A14: 4
A15: 5
A16: 6
A17: 7
A18: 8
A19: 9
A20: 10
A21: 11
A22: 12
A23: 13
... A27: 17
A28: Total | H28: =SUM(H11:H27) -> 240000
A29: PPN 11% | H29: =H28*11% -> 26400
A30: PPH 22 | H30: =H28*1.5% -> 3600
A31: PPH 23 | H31: =FAKTUR!M13 -> 0
A32: Total + PPN | H32: =FAKTUR!N22 -> 2536350
A33: Terbilang :
A34: =KWITANSI!B14 -> Dua Juta Lima Ratus Tiga Puluh Enam Ribu Tiga Ratus Lima Puluh Rupiah
B37: =[2]BAPP!B40 -> PIHAK KEDUA | K37: =[2]BAPP!J40 -> PIHAK PERTAMA,
B38: =[2]BAPP!B41 -> PENGGUNA ANGGARAN | K38: =[2]BAPP!J41 -> CV. Pustaka Cemerlang Indonesia
B39: =[2]BAPP!B42 -> Kepala | C39: =BAPP!C42 -> SDN Kebon Kosong 09 | K39: =[2]BAPP!J42 -> Direktur Utama
B45: ='SURAT PESANAN (2)'!I48 -> Khairunnisa | K45: =BAPP!J48 -> Bambang Solifian
B46: =BAPB!F61 -> NIP. 198402112011012010

Sheet BAST Rekanan
A1: PEMERINTAH PROVINSI DAERAH KHUSUS IBUKOTA JAKARTA
A2: DINAS PENDIDIKAN DASAR
A3: SUKU DINAS PENDIDIKAN WILAYAH II KOTA ADMINISTRASI JAKARTA PUSAT
A4: =BAPB!A4 -> Jl. Kemayoran Gempol no.32 RT 015.05
A5: =BAPB!A5 -> 0
D6: =BAPB!D6 -> Jakarta Pusat 10630 email :sdnkk05pg@gmail.com | K6: =BAPB!J6 -> 0
A8: BERITA ACARA SERAH TERIMA BARANG
A9: 02/BAST-PCI/KK13/2022
B11: =BAPB!B11 -> Pada hari ini, Selasa Tanggal Enam Belas bulan Juni Tahun Dua Ribu Dua Puluh Enam yang bertanda tangan dibawah ini :
B12: =BAPB!B20 -> Nama | C12: : | D12: =BAPB!D20 -> Bambang Solifian
B13: =BAPB!B21 -> Jabatan | C13: : | D13: =BAPB!D21 -> Direktur
B14: =BAPB!B22 -> Perusahaan | C14: : | D14: =BAPB!D22 -> CV. PUSTAKA CEMERLANG INDONESIA
B15: =BAPB!B23 -> Alamat | C15: : | D15: =BAPB!D23 -> Wisma Mitra Sunter 3-03
D16: =BAPB!D24 -> Jl. Yos Sudarso Kav. 89, Boulevard Mitra Sunter Blok C2, Sunter Jaya, Tanjung Priok
B18: Dalam hal ini bertindak untuk dan atas nama CV. PUSTAKA CEMERLANG INDONESIA, Selanjutnya disebut sebagai PIHAK PERTAMA,
B20: =BAPB!B12 -> Nama | C20: : | D20: =BAPB!D12 -> Sulistiawati
B21: =BAPB!B13 -> Jabatan | C21: : | D21: =BAPB!D13 -> Pengurus Barang
B22: =BAPB!B14 -> NIP | C22: : | D22: =BAPB!D14 -> 197909092022212008
B23: =BAPB!B15 -> Instansi | C23: : | D23: =BAPB!D15 -> SDN Kebon Kosong 09
B24: =BAPB!B16 -> Alamat | D24: =BAPB!D16 -> Jl. Kemayoran Gempol no.32
B26: Dalam hal ini bertindak untuk dan atas nama Sekolah, Selanjutnya disebut sebagai PIHAK KEDUA,
B28: Dengan ini PIHAK PERTAMA telah menyerahkan kepada PIHAK KEDUA, dan PIHAK KEDUA telah menerima penyerahan barang dari
B29: PIHAK PERTAMA dalam jumlah yang lengkap dan kondisi yang baik, dengan rincian:
B31: No | C31: Nama Barang / Jasa | F31: Kuantitas | H31: Kondisi Barang
B32: =BAPB!B32 -> 1 | C32: =BAPB!C32 -> glass cleaner | F32: =BAPB!G32 -> 15 | G32: =BAPB!H32 -> liter | H32: =BAPB!I32 -> Baik
B34: Dengan adanya berita Acara Serah Terima barang ini maka Pekerjaan PIHAK KEDUA telah selesai melaksanakan kewajibannya
B35: dengan baik dan berhak menerima pembayaran dari PIHAK PERTAMA.
B37: Demikian Berita Acara Serah Terima ini dibuat untuk dapat dipergunakan sebagaimana mestinya.
B39: Yang Menyerahkan, | J39: Yang Menerima,
B40: PIHAK PERTAMA | J40: PIHAK KEDUA
B46: =BAPB!I49 -> Bambang Solifian | J46: =BAPB!B49 -> Sulistiawati
J47: =BAPB!B50 -> NIP. 197909092022212008
G49: =BAPB!F53 -> Mengetahui,
G50: =BAPB!F54 -> Kepala Sekolah SDN Kebon Kosong 09
G56: =BAPB!F60 -> Khairunnisa
G57: =BAPB!F61 -> NIP. 198402112011012010
